public void testIssue108() {
    try {
        System.out.println(compile("function name() { var arguments = Array.prototype.slice.call(arguments, 0); }"));
        fail("Should have thrown exception");
    } catch (Exception e) {
        assertThat(e.getMessage(), containsString("\"arguments\""));
        assertThat(e.getMessage(), containsString("\"c\""));
    }
}
